[2025-02-20T09:40:11.112+0000] {local_task_job_runner.py:123} INFO - ::group::Pre task execution logs
[2025-02-20T09:40:11.134+0000] {taskinstance.py:2614} INFO - Dependencies all met for dep_context=non-requeueable deps ti=<TaskInstance: weather_to_postgres_hook.fetch_weather manual__2025-02-20T09:40:08.207005+00:00 [queued]>
[2025-02-20T09:40:11.141+0000] {taskinstance.py:2614} INFO - Dependencies all met for dep_context=requeueable deps ti=<TaskInstance: weather_to_postgres_hook.fetch_weather manual__2025-02-20T09:40:08.207005+00:00 [queued]>
[2025-02-20T09:40:11.141+0000] {taskinstance.py:2867} INFO - Starting attempt 1 of 2
[2025-02-20T09:40:11.155+0000] {taskinstance.py:2890} INFO - Executing <Task(PythonOperator): fetch_weather> on 2025-02-20 09:40:08.207005+00:00
[2025-02-20T09:40:11.165+0000] {warnings.py:112} WARNING - /home/***/.local/lib/python3.12/site-packages/***/task/task_runner/standard_task_runner.py:70: DeprecationWarning: This process (pid=507) is multi-threaded, use of fork() may lead to deadlocks in the child.
  pid = os.fork()

[2025-02-20T09:40:11.167+0000] {standard_task_runner.py:72} INFO - Started process 509 to run task
[2025-02-20T09:40:11.167+0000] {standard_task_runner.py:104} INFO - Running: ['***', 'tasks', 'run', 'weather_to_postgres_hook', 'fetch_weather', 'manual__2025-02-20T09:40:08.207005+00:00', '--job-id', '49', '--raw', '--subdir', 'DAGS_FOLDER/etl_weather.py', '--cfg-path', '/tmp/tmpkr6dvfae']
[2025-02-20T09:40:11.168+0000] {standard_task_runner.py:105} INFO - Job 49: Subtask fetch_weather
[2025-02-20T09:40:11.213+0000] {task_command.py:467} INFO - Running <TaskInstance: weather_to_postgres_hook.fetch_weather manual__2025-02-20T09:40:08.207005+00:00 [running]> on host 9f470da8c4e6
[2025-02-20T09:40:11.298+0000] {taskinstance.py:3134} INFO - Exporting env vars: AIRFLOW_CTX_DAG_OWNER='***' AIRFLOW_CTX_DAG_ID='weather_to_postgres_hook' AIRFLOW_CTX_TASK_ID='fetch_weather' AIRFLOW_CTX_EXECUTION_DATE='2025-02-20T09:40:08.207005+00:00' AIRFLOW_CTX_TRY_NUMBER='1' AIRFLOW_CTX_DAG_RUN_ID='manual__2025-02-20T09:40:08.207005+00:00'
[2025-02-20T09:40:11.300+0000] {logging_mixin.py:190} INFO - Task instance is in running state
[2025-02-20T09:40:11.300+0000] {logging_mixin.py:190} INFO -  Previous state of the Task instance: queued
[2025-02-20T09:40:11.301+0000] {logging_mixin.py:190} INFO - Current task name:fetch_weather state:running start_date:2025-02-20 09:40:11.134714+00:00
[2025-02-20T09:40:11.301+0000] {logging_mixin.py:190} INFO - Dag name:weather_to_postgres_hook and current dag run status:running
[2025-02-20T09:40:11.301+0000] {taskinstance.py:732} INFO - ::endgroup::
[2025-02-20T09:40:11.312+0000] {base.py:84} INFO - Retrieving connection 'openweather_api'
[2025-02-20T09:40:12.040+0000] {http.py:239} ERROR - HTTP error: Not Found
[2025-02-20T09:40:12.041+0000] {http.py:240} ERROR - <html>
<head><title>404 Not Found</title></head>
<body>
<center><h1>404 Not Found</h1></center>
<hr><center>openresty</center>
</body>
</html>

[2025-02-20T09:40:12.052+0000] {taskinstance.py:3313} ERROR - Task failed with exception
Traceback (most recent call last):
  File "/home/airflow/.local/lib/python3.12/site-packages/airflow/providers/http/hooks/http.py", line 237, in check_response
    response.raise_for_status()
  File "/home/airflow/.local/lib/python3.12/site-packages/requests/models.py", line 1024, in raise_for_status
    raise HTTPError(http_error_msg, response=self)
requests.exceptions.HTTPError: 404 Client Error: Not Found for url: https://api.openweathermap.org/https://api.openweathermap.org/data/2.5/weather?lat=-6.200&lon=106.8166&appid=29a0846575fdc9d8ced175de4ed56770

During handling of the above exception, another exception occurred:

Traceback (most recent call last):
  File "/home/airflow/.local/lib/python3.12/site-packages/airflow/models/taskinstance.py", line 768, in _execute_task
    result = _execute_callable(context=context, **execute_callable_kwargs)
             ^^^^^^^^^^^^^^^^^^^^^^^^^^^^^^^^^^^^^^^^^^^^^^^^^^^^^^^^^^^^^
  File "/home/airflow/.local/lib/python3.12/site-packages/airflow/models/taskinstance.py", line 734, in _execute_callable
    return ExecutionCallableRunner(
           ^^^^^^^^^^^^^^^^^^^^^^^^
  File "/home/airflow/.local/lib/python3.12/site-packages/airflow/utils/operator_helpers.py", line 252, in run
    return self.func(*args, **kwargs)
           ^^^^^^^^^^^^^^^^^^^^^^^^^^
  File "/home/airflow/.local/lib/python3.12/site-packages/airflow/models/baseoperator.py", line 424, in wrapper
    return func(self, *args, **kwargs)
           ^^^^^^^^^^^^^^^^^^^^^^^^^^^
  File "/home/airflow/.local/lib/python3.12/site-packages/airflow/operators/python.py", line 238, in execute
    return_value = self.execute_callable()
                   ^^^^^^^^^^^^^^^^^^^^^^^
  File "/home/airflow/.local/lib/python3.12/site-packages/airflow/operators/python.py", line 256, in execute_callable
    return runner.run(*self.op_args, **self.op_kwargs)
           ^^^^^^^^^^^^^^^^^^^^^^^^^^^^^^^^^^^^^^^^^^^
  File "/home/airflow/.local/lib/python3.12/site-packages/airflow/utils/operator_helpers.py", line 252, in run
    return self.func(*args, **kwargs)
           ^^^^^^^^^^^^^^^^^^^^^^^^^^
  File "/opt/airflow/dags/etl_weather.py", line 36, in fetch_weather
    response=http_hook.run(endpoint)
             ^^^^^^^^^^^^^^^^^^^^^^^
  File "/home/airflow/.local/lib/python3.12/site-packages/airflow/providers/http/hooks/http.py", line 226, in run
    return self.run_and_check(session, prepped_request, extra_options)
           ^^^^^^^^^^^^^^^^^^^^^^^^^^^^^^^^^^^^^^^^^^^^^^^^^^^^^^^^^^^
  File "/home/airflow/.local/lib/python3.12/site-packages/airflow/providers/http/hooks/http.py", line 279, in run_and_check
    self.check_response(response)
  File "/home/airflow/.local/lib/python3.12/site-packages/airflow/providers/http/hooks/http.py", line 241, in check_response
    raise AirflowException(str(response.status_code) + ":" + response.reason)
airflow.exceptions.AirflowException: 404:Not Found
[2025-02-20T09:40:12.067+0000] {logging_mixin.py:190} INFO - Task instance in failure state
[2025-02-20T09:40:12.067+0000] {logging_mixin.py:190} INFO - Task start:2025-02-20 09:40:11.134714+00:00 end:2025-02-20 09:40:12.066835+00:00 duration:0.932121
[2025-02-20T09:40:12.068+0000] {logging_mixin.py:190} INFO - Task:<Task(PythonOperator): fetch_weather> dag:<DAG: weather_to_postgres_hook> dagrun:<DagRun weather_to_postgres_hook @ 2025-02-20 09:40:08.207005+00:00: manual__2025-02-20T09:40:08.207005+00:00, state:running, queued_at: 2025-02-20 09:40:08.248630+00:00. externally triggered: True>
[2025-02-20T09:40:12.068+0000] {logging_mixin.py:190} INFO - Failure caused by 404:Not Found
[2025-02-20T09:40:12.069+0000] {taskinstance.py:1226} INFO - Marking task as UP_FOR_RETRY. dag_id=weather_to_postgres_hook, task_id=fetch_weather, run_id=manual__2025-02-20T09:40:08.207005+00:00, execution_date=20250220T094008, start_date=20250220T094011, end_date=20250220T094012
[2025-02-20T09:40:12.098+0000] {taskinstance.py:341} INFO - ::group::Post task execution logs
[2025-02-20T09:40:12.099+0000] {standard_task_runner.py:124} ERROR - Failed to execute job 49 for task fetch_weather (404:Not Found; 509)
Traceback (most recent call last):
  File "/home/airflow/.local/lib/python3.12/site-packages/airflow/providers/http/hooks/http.py", line 237, in check_response
    response.raise_for_status()
  File "/home/airflow/.local/lib/python3.12/site-packages/requests/models.py", line 1024, in raise_for_status
    raise HTTPError(http_error_msg, response=self)
requests.exceptions.HTTPError: 404 Client Error: Not Found for url: https://api.openweathermap.org/https://api.openweathermap.org/data/2.5/weather?lat=-6.200&lon=106.8166&appid=29a0846575fdc9d8ced175de4ed56770

During handling of the above exception, another exception occurred:

Traceback (most recent call last):
  File "/home/airflow/.local/lib/python3.12/site-packages/airflow/task/task_runner/standard_task_runner.py", line 117, in _start_by_fork
    ret = args.func(args, dag=self.dag)
          ^^^^^^^^^^^^^^^^^^^^^^^^^^^^^
  File "/home/airflow/.local/lib/python3.12/site-packages/airflow/cli/cli_config.py", line 49, in command
    return func(*args, **kwargs)
           ^^^^^^^^^^^^^^^^^^^^^
  File "/home/airflow/.local/lib/python3.12/site-packages/airflow/utils/cli.py", line 116, in wrapper
    return f(*args, **kwargs)
           ^^^^^^^^^^^^^^^^^^
  File "/home/airflow/.local/lib/python3.12/site-packages/airflow/cli/commands/task_command.py", line 483, in task_run
    task_return_code = _run_task_by_selected_method(args, _dag, ti)
                       ^^^^^^^^^^^^^^^^^^^^^^^^^^^^^^^^^^^^^^^^^^^^
  File "/home/airflow/.local/lib/python3.12/site-packages/airflow/cli/commands/task_command.py", line 256, in _run_task_by_selected_method
    return _run_raw_task(args, ti)
           ^^^^^^^^^^^^^^^^^^^^^^^
  File "/home/airflow/.local/lib/python3.12/site-packages/airflow/cli/commands/task_command.py", line 341, in _run_raw_task
    return ti._run_raw_task(
           ^^^^^^^^^^^^^^^^^
  File "/home/airflow/.local/lib/python3.12/site-packages/airflow/utils/session.py", line 97, in wrapper
    return func(*args, session=session, **kwargs)
           ^^^^^^^^^^^^^^^^^^^^^^^^^^^^^^^^^^^^^^
  File "/home/airflow/.local/lib/python3.12/site-packages/airflow/models/taskinstance.py", line 3006, in _run_raw_task
    return _run_raw_task(
           ^^^^^^^^^^^^^^
  File "/home/airflow/.local/lib/python3.12/site-packages/airflow/models/taskinstance.py", line 274, in _run_raw_task
    TaskInstance._execute_task_with_callbacks(
  File "/home/airflow/.local/lib/python3.12/site-packages/airflow/models/taskinstance.py", line 3161, in _execute_task_with_callbacks
    result = self._execute_task(context, task_orig)
             ^^^^^^^^^^^^^^^^^^^^^^^^^^^^^^^^^^^^^^
  File "/home/airflow/.local/lib/python3.12/site-packages/airflow/models/taskinstance.py", line 3185, in _execute_task
    return _execute_task(self, context, task_orig)
           ^^^^^^^^^^^^^^^^^^^^^^^^^^^^^^^^^^^^^^^
  File "/home/airflow/.local/lib/python3.12/site-packages/airflow/models/taskinstance.py", line 768, in _execute_task
    result = _execute_callable(context=context, **execute_callable_kwargs)
             ^^^^^^^^^^^^^^^^^^^^^^^^^^^^^^^^^^^^^^^^^^^^^^^^^^^^^^^^^^^^^
  File "/home/airflow/.local/lib/python3.12/site-packages/airflow/models/taskinstance.py", line 734, in _execute_callable
    return ExecutionCallableRunner(
           ^^^^^^^^^^^^^^^^^^^^^^^^
  File "/home/airflow/.local/lib/python3.12/site-packages/airflow/utils/operator_helpers.py", line 252, in run
    return self.func(*args, **kwargs)
           ^^^^^^^^^^^^^^^^^^^^^^^^^^
  File "/home/airflow/.local/lib/python3.12/site-packages/airflow/models/baseoperator.py", line 424, in wrapper
    return func(self, *args, **kwargs)
           ^^^^^^^^^^^^^^^^^^^^^^^^^^^
  File "/home/airflow/.local/lib/python3.12/site-packages/airflow/operators/python.py", line 238, in execute
    return_value = self.execute_callable()
                   ^^^^^^^^^^^^^^^^^^^^^^^
  File "/home/airflow/.local/lib/python3.12/site-packages/airflow/operators/python.py", line 256, in execute_callable
    return runner.run(*self.op_args, **self.op_kwargs)
           ^^^^^^^^^^^^^^^^^^^^^^^^^^^^^^^^^^^^^^^^^^^
  File "/home/airflow/.local/lib/python3.12/site-packages/airflow/utils/operator_helpers.py", line 252, in run
    return self.func(*args, **kwargs)
           ^^^^^^^^^^^^^^^^^^^^^^^^^^
  File "/opt/airflow/dags/etl_weather.py", line 36, in fetch_weather
    response=http_hook.run(endpoint)
             ^^^^^^^^^^^^^^^^^^^^^^^
  File "/home/airflow/.local/lib/python3.12/site-packages/airflow/providers/http/hooks/http.py", line 226, in run
    return self.run_and_check(session, prepped_request, extra_options)
           ^^^^^^^^^^^^^^^^^^^^^^^^^^^^^^^^^^^^^^^^^^^^^^^^^^^^^^^^^^^
  File "/home/airflow/.local/lib/python3.12/site-packages/airflow/providers/http/hooks/http.py", line 279, in run_and_check
    self.check_response(response)
  File "/home/airflow/.local/lib/python3.12/site-packages/airflow/providers/http/hooks/http.py", line 241, in check_response
    raise AirflowException(str(response.status_code) + ":" + response.reason)
airflow.exceptions.AirflowException: 404:Not Found
[2025-02-20T09:40:12.130+0000] {local_task_job_runner.py:266} INFO - Task exited with return code 1
[2025-02-20T09:40:12.154+0000] {taskinstance.py:3901} INFO - 0 downstream tasks scheduled from follow-on schedule check
[2025-02-20T09:40:12.155+0000] {local_task_job_runner.py:245} INFO - ::endgroup::
